Workbook
Name BUSINESS_TYPE_COLUMNS: #REF!
Name BUSS_TYPE_COLUMNS: #REF!
Name BUSS_TYPE_LISTS: #REF!
Name CA.R.2_Features_of_instruments_SUM: 'CA.R.2 Features of instruments'!$E$15:$T$15,'CA.R.2 Features of instruments'!$E$17:$T$17,'CA.R.2 Features of instruments'!$E$21:$T$21
Name checksum_F.LT.3: 'F.LT.3 TVOG'!$F$10:$I$26
Name DEV_MODE: #REF!
Name F.A.3B_End_Column_0: 'F.A.3B Qualitative Assessment'!$J$8
Name F.A.3B_Start_Column_0: 'F.A.3B Qualitative Assessment'!$D$8
Name FinancialMonth: #REF!
Name FinancialYear: #REF!
Name FORMULA_COLOR: #REF!
Name FORMULA_COLOR_SAMPLE: #REF!
Name INSURANCE_HEAD: #REF!
Name QDAP_Full_Columns: #REF!
Name QDAP_ON_OFF: #REF!
Name QDAP_WORKSHEETS: #REF!
Name ReportMonth: #REF!
Name ReportYearEndDate: #REF!
Name RULE_CAPG7A_C116: 'CA.P.G.7A_NatCat_Own_Scope'!$C$116
Name RULE_CAPG7A_D120D123: 'CA.P.G.7A_NatCat_Own_Scope'!$D$120:$D$123
Name RULE_CAPG7A_D125: 'CA.P.G.7A_NatCat_Own_Scope'!$D$125
Name RULE_CAPG7E_C96: 'CA.P.G.7E_NatCat_Own_YoYChange'!$C$96
Name RULE_CAPG7E_C97: 'CA.P.G.7E_NatCat_Own_YoYChange'!$C$97
Name RULE_CAPLT2_I3014I3021: 'CA.P.LT.2 HRG'!$I$3014:$I$3021
Name RULE_CAPLT2_J3014J3021: 'CA.P.LT.2 HRG'!$J$3014:$J$3021
Name RULE_CAPLT3_J3014J3023: 'CA.P.LT.3 Product'!$J$3014:$J$3023
Name RULE_CAPLT3_K3014K3023: 'CA.P.LT.3 Product'!$K$3014:$K$3023
Name RULE_CAPLT4_G26: 'CA.P.LT.4 HRGvsProduct'!$G$26
Name RULE_DATE_O18: 'F.A.6A Port Inv of Port Inv'!$O$18:$O$24
Name RULE_DATE_S18: 'F.A.6 Port Inv'!$S$18:$S$29
Name RULE_DATE_T18: 'F.A.6 Port Inv'!$T$18:$T$29
Name RULE_F3_C35F35: 'F.3 AOM'!$C$35:$F$35
Name RULE_F3_C36F36: 'F.3 AOM'!$C$36:$F$36
Name RULE_F3_C38F38: 'F.3 AOM'!$C$38:$F$38
Name RULE_F3_C39F39: 'F.3 AOM'!$C$39:$F$39
Name RULE_F3_F35: 'F.3 AOM'!$F$35
Name RULE_F3_F36: 'F.3 AOM'!$F$36
Name RULE_FA4_G7576: 'F.A.4 Derivatives'!$G$75:$G$76
Name RULE_FA4_S1160: 'F.A.4 Derivatives'!$S$11:$S$60
Name RULE_FA4_T6569: 'F.A.4 Derivatives'!$T$65:$T$69
Name RULE_FA4_U6569: 'F.A.4 Derivatives'!$U$65:$U$69
Name RULE_FA6_AE29: 'F.A.6 Port Inv'!$AE$29
Name RULE_FA6_H33: 'F.A.6 Port Inv'!$H$33
Name RULE_FA6_H34: 'F.A.6 Port Inv'!$H$34
Name RULE_FA6_H35: 'F.A.6 Port Inv'!$H$35
Name RULE_FA6_I34: 'F.A.6 Port Inv'!$I$34
Name RULE_FA6_I35: 'F.A.6 Port Inv'!$I$35
Name RULE_FA6_M18M27: 'F.A.6 Port Inv'!$M$18:$M$27
Name RULE_FA6_U29: 'F.A.6 Port Inv'!$U$29
Name RULE_FA6_V29: 'F.A.6 Port Inv'!$V$29
Name RULE_FA6_W29: 'F.A.6 Port Inv'!$W$29
Name RULE_FA6_X29: 'F.A.6 Port Inv'!$X$29
Name RULE_FA6_Y29: 'F.A.6 Port Inv'!$Y$29
Name RULE_FA6A_G28: 'F.A.6A Port Inv of Port Inv'!$G$28
Name RULE_FA6A_G29: 'F.A.6A Port Inv of Port Inv'!$G$29
Name RULE_FA6A_G30: 'F.A.6A Port Inv of Port Inv'!$G$30
Name RULE_FA6A_H30: 'F.A.6A Port Inv of Port Inv'!$H$30
Name RULE_FA7_N1016: 'F.A.7 Related Parties'!$N$10:$N$16
Name RULE_FA7_O1016: 'F.A.7 Related Parties'!$O$10:$O$16
Name RULE_FT6_C85I85: 'F.LT.6 Par Business'!$C$85:$I$85

Sheet F.1 EBS
A1: F.1 Regulatory balance sheet
A2: Name of Insurer: | B2: ='Cover Page'!F15
A3: Valuation Date: | B3: 31 Dec 2025
A4: Reporting Period:
A7: (Unit: in HKD thousands) | H7: Long term offshore reinsurance business | J7: General offshore reinsurance business
D8: For branch operating in Hong Kong (other than a designated insurer), whether offshore reinsurance fund is established?
A11: Column 1 | B11: Column 2 | C11: Column 3 | D11: Column 4 | E11: Column 5 | F11: Column 6 | G11: Column 7 | H11: Column 8 | I11: Column 9 | J11: Column 10 | K11: Column 11 | L11: Column 12 | N11: Column 13 | O11: Column 14 | P11: Column 15 | Q11: Column 16 | R11: Column 17 | S11: Column 18 | T11: Column 19 | U11: Column 20 | W11: Column 21 | X11: Column 22 | Z11: Column 23 | AA11: Column 24 | AB11: Column 25 | AC11: Column 26 | AD11: Column 27 | AE11: Column 28 | AF11: Column 29 | AG11: Column 30 | AH11: Column 31 | AI11: Column 32 | AJ11: Column 33
A12: Asset / Liability / Capital Items | B12: (a) | C12: (b) | D12: (c) | E12: (d) | F12: (e) | G12: (f) | H12: (g) | I12: (h) | J12: (i) | K12: (j) | L12: (k) | N12: (l) | O12: (m) | P12: (n) | Q12: (o) | R12: (p) | S12: (q) | T12: (r) | U12: (s) | W12: (t) | X12: (u) | Z12: (v) | AA12: (w) | AB12: (x) | AC12: (w) | AD12: (x) | AE12: (y) | AF12: (z) | AG12: (aa) | AH12: (ab) | AI12: (ac) | AJ12: (ad)
B13: Carrying values under scope of regulatory consolidation | C13: Carrying values under scope of regulatory consolidation | W13: Carrying values under scope of regulatory consolidation | Z13: General Insurance Liabilities breakdown for public disclosure
C14: Long Term Insurance Business | I14: General Insurance Business | K14: Non-insurance operations | L14: Shareholder Fund | N14: Applicable to HK insurers or designated insurers: Of which belongs to Branch insurance operations outside Hong Kong (Please fill in the jurisdiction of each branch operation outside Hong Kong in the row below) | W14: Total Long Term Insurance Business | X14: Total General Insurance Business | AA14: Direct | AH14: Reinsurance | AJ14: Total
C15: HK insurers or designated insurers: all long term insurance business Branch operating in Hong Kong: all long term insurance business, other than offshore RI business if offshore RI fund is established | H15: Applicable to branch operating in Hong Kong with offshore RI fund established: Offshore RI business related | I15: HK insurers or designated insurers: all general insurance business Branch operating in Hong Kong: all general insurance business, other than offshore RI business if offshore RI fund is established | J15: Applicable to branch operating in Hong Kong with offshore RI fund established: Offshore RI business related | N15: (Jurisdiction) Branch 1 | P15: (Jurisdiction) Branch 2 | R15: (Jurisdiction) Branch 3 | T15: (Jurisdiction) Branch 4 | AA15: Accident & Health | AB15: Motor Vehicle | AC15: Marine, Aviation, and Transport | AD15: Property Damage | AE15: Employees' Compensation | AF15: General Liability | AG15: Pecuniary Loss | AH15: Proportional | AI15: Non-Proportional
C16: Linked Long Term (Class C) | D16: Retirement scheme category I (Class G) | E16: Retirement scheme category II (Class H) | F16: Participating Business | G16: Other Businesses | N16: Total carrying values of the branch | O16: Of which belongs to Long Term Fund | P16: Total carrying values of the branch | Q16: Of which belongs to Long Term Fund | R16: Total carrying values of the branch | S16: Of which belongs to Long Term Fund | T16: Total carrying values of the branch | U16: Of which belongs to Long Term Fund
A17: Description | B17: As at the end of reporting period | N17: As at the end of reporting period
B18: (T)
A19: I – Total assets | Z19: Gross Outstanding Claims Liabilities excluding MOCE | AA19: ='F.G.1_ClaimLiab'!C12+'F.G.1_ClaimLiab'!C29-AA20 | AB19: ='F.G.1_ClaimLiab'!C13+'F.G.1_ClaimLiab'!C30-AB20 | AC19: =SUM('F.G.1_ClaimLiab'!C14:C16,'F.G.1_ClaimLiab'!C31:C33)-AC20 | AD19: ='F.G.1_ClaimLiab'!C17+'F.G.1_ClaimLiab'!C34-AD20 | AE19: ='F.G.1_ClaimLiab'!C18+'F.G.1_ClaimLiab'!C35-AE20 | AF19: ='F.G.1_ClaimLiab'!C21+'F.G.1_ClaimLiab'!C38-AF20 | AG19: ='F.G.1_ClaimLiab'!C24+'F.G.1_ClaimLiab'!C41-AG20 | AH19: ='F.G.1_ClaimLiab'!C46+'F.G.1_ClaimLiab'!C60+'F.G.1_ClaimLiab'!C96+'F.G.1_ClaimLiab'!C110-AH20 | AI19: ='F.G.1_ClaimLiab'!C74+'F.G.1_ClaimLiab'!C85+'F.G.1_ClaimLiab'!C124+'F.G.1_ClaimLiab'!C135-AI20 | AJ19: =SUM(AA19:AI19)
A20: I.A. Goodwill | Z20: Gross Outstanding Claims Liabilities MOCE | AA20: ='F.G.1_ClaimLiab'!J12+'F.G.1_ClaimLiab'!J29 | AB20: ='F.G.1_ClaimLiab'!J13+'F.G.1_ClaimLiab'!J30 | AC20: =SUM('F.G.1_ClaimLiab'!J14:J16,'F.G.1_ClaimLiab'!J31:J33) | AD20: ='F.G.1_ClaimLiab'!J17+'F.G.1_ClaimLiab'!J34 | AE20: ='F.G.1_ClaimLiab'!J18+'F.G.1_ClaimLiab'!J35 | AF20: ='F.G.1_ClaimLiab'!J21+'F.G.1_ClaimLiab'!J38 | AG20: ='F.G.1_ClaimLiab'!J24+'F.G.1_ClaimLiab'!J41 | AH20: ='F.G.1_ClaimLiab'!J46+'F.G.1_ClaimLiab'!J60+'F.G.1_ClaimLiab'!J96+'F.G.1_ClaimLiab'!J110 | AI20: ='F.G.1_ClaimLiab'!J74+'F.G.1_ClaimLiab'!J85+'F.G.1_ClaimLiab'!J124+'F.G.1_ClaimLiab'!J135 | AJ20: =SUM(AA20:AI20)
A21: I.B. Intangible assets | Z21: Gross Premium Liabilities excluding MOCE | AA21: ='F.G.2_PL'!C12+'F.G.2_PL'!C29-AA22 | AB21: ='F.G.2_PL'!C13+'F.G.2_PL'!C30-AB22 | AC21: =SUM('F.G.2_PL'!C14:C16,'F.G.2_PL'!C31:C33)-AC22 | AD21: ='F.G.2_PL'!C17+'F.G.2_PL'!C34-AD22 | AE21: ='F.G.2_PL'!C18+'F.G.2_PL'!C35-AE22 | AF21: ='F.G.2_PL'!C21+'F.G.2_PL'!C38-AF22 | AG21: ='F.G.2_PL'!C24+'F.G.2_PL'!C41-AG22 | AH21: ='F.G.2_PL'!C46+'F.G.2_PL'!C60+'F.G.2_PL'!C96+'F.G.2_PL'!C110-AH22 | AI21: ='F.G.2_PL'!C74+'F.G.2_PL'!C85+'F.G.2_PL'!C124+'F.G.2_PL'!C135-AI22 | AJ21: =SUM(AA21:AI21)
A22: I.C. Cash and cash equivalents, and statutory deposits | B22: 2850 | C22: =SUM(C23:C24) | D22: =SUM(D23:D24) | E22: =SUM(E23:E24) | F22: =SUM(F23:F24) | G22: =SUM(G23:G24) | H22: =SUM(H23:H24) | I22: =SUM(I23:I24) | J22: =SUM(J23:J24) | ... L22: =SUM(L23:L24) | N22: =SUM(N23:N24) | P22: =SUM(P23:P24) | R22: =SUM(R23:R24) | T22: =SUM(T23:T24) | W22: =SUM(C22:H22) | X22: =SUM(I22:J22) | Z22: Gross Premium Liabilities MOCE | AA22: ='F.G.2A_PL_Recog'!K12+'F.G.2A_PL_Recog'!K29+'F.G.2B_PL_notRecog'!K12+'F.G.2B_PL_notRecog'!K29 | AB22: ='F.G.2A_PL_Recog'!K13+'F.G.2A_PL_Recog'!K30+'F.G.2B_PL_notRecog'!K13+'F.G.2B_PL_notRecog'!K30 | AC22: =SUM('F.G.2A_PL_Recog'!K14:K16,'F.G.2A_PL_Recog'!K31:K33)+SUM('F.G.2B_PL_notRecog'!K14:K16,'F.G.2B_PL_notRecog'!K31:K33) | AD22: ='F.G.2A_PL_Recog'!K17+'F.G.2A_PL_Recog'!K34+'F.G.2B_PL_notRecog'!K17+'F.G.2B_PL_notRecog'!K34 | AE22: ='F.G.2A_PL_Recog'!K18+'F.G.2A_PL_Recog'!K35+'F.G.2B_PL_notRecog'!K18+'F.G.2B_PL_notRecog'!K35 | AF22: ='F.G.2A_PL_Recog'!K21+'F.G.2A_PL_Recog'!K38+'F.G.2B_PL_notRecog'!K21+'F.G.2B_PL_notRecog'!K38 | AG22: ='F.G.2A_PL_Recog'!K24+'F.G.2A_PL_Recog'!K41+'F.G.2B_PL_notRecog'!K24+'F.G.2B_PL_notRecog'!K41 | AH22: ='F.G.2A_PL_Recog'!K46+'F.G.2A_PL_Recog'!K60+'F.G.2A_PL_Recog'!K96+'F.G.2A_PL_Recog'!K110+'F.G.2B_PL_notRecog'!K46+'F.G.2B_PL_notRecog'!K60+'F.G.2B_PL_notRecog'!K96+'F.G.2B_PL_notRecog'!K110 | AI22: ='F.G.2A_PL_Recog'!K74+'F.G.2A_PL_Recog'!K85+'F.G.2A_PL_Recog'!K124+'F.G.2A_PL_Recog'!K135+'F.G.2B_PL_notRecog'!K74+'F.G.2B_PL_notRecog'!K85+'F.G.2B_PL_notRecog'!K124+'F.G.2B_PL_notRecog'!K135 | AJ22: =SUM(AA22:AI22)
A23: I.C1. Statutory deposits | B23: 1200 | W23: =SUM(C23:H23) | X23: =SUM(I23:J23) | Z23: Gross General insurance liabilities excluding 'Other General Insurance Liabilties' | AA23: =SUM(AA19:AA22) | AB23: =SUM(AB19:AB22) | AC23: =SUM(AC19:AC22) | AD23: =SUM(AD19:AD22) | AE23: =SUM(AE19:AE22) | AF23: =SUM(AF19:AF22) | AG23: =SUM(AG19:AG22) | AH23: =SUM(AH19:AH22) | AI23: =SUM(AI19:AI22) | AJ23: =SUM(AA23:AI23)
A24: I.C2. Non-statutory or other deposits | B24: 1650 | W24: =SUM(C24:H24) | X24: =SUM(I24:J24) | Z24: Net General insurance liabilities excluding 'Other General Insurance Liabilties' | AA24: ='F.G.1_ClaimLiab'!E12+'F.G.1_ClaimLiab'!E29+'F.G.2_PL'!E12+'F.G.2_PL'!E29 | AB24: ='F.G.1_ClaimLiab'!E13+'F.G.1_ClaimLiab'!E30+'F.G.2_PL'!E13+'F.G.2_PL'!E30 | AC24: =SUM('F.G.1_ClaimLiab'!E14:E16,'F.G.1_ClaimLiab'!E31:E33)+SUM('F.G.2_PL'!E14:E16,'F.G.2_PL'!E31:E33) | AD24: ='F.G.1_ClaimLiab'!E17+'F.G.1_ClaimLiab'!E34+'F.G.2_PL'!E17+'F.G.2_PL'!E34 | AE24: ='F.G.1_ClaimLiab'!E18+'F.G.1_ClaimLiab'!E35+'F.G.2_PL'!E18+'F.G.2_PL'!E35 | AF24: ='F.G.1_ClaimLiab'!E21+'F.G.1_ClaimLiab'!E38+'F.G.2_PL'!E21+'F.G.2_PL'!E38 | AG24: ='F.G.1_ClaimLiab'!E24+'F.G.1_ClaimLiab'!E41+'F.G.2_PL'!E24+'F.G.2_PL'!E41 | AH24: ='F.G.1_ClaimLiab'!E46+'F.G.1_ClaimLiab'!E60+'F.G.1_ClaimLiab'!E96+'F.G.1_ClaimLiab'!E110+'F.G.2_PL'!E46+'F.G.2_PL'!E60+'F.G.2_PL'!E96+'F.G.2_PL'!E110 | AI24: ='F.G.1_ClaimLiab'!E74+'F.G.1_ClaimLiab'!E85+'F.G.1_ClaimLiab'!E124+'F.G.1_ClaimLiab'!E135+'F.G.2_PL'!E74+'F.G.2_PL'!E85+'F.G.2_PL'!E124+'F.G.2_PL'!E135 | AJ24: =SUM(AA24:AI24)
A25: I.D. Deposits with original maturity more than three months | B25: =SUM(C25:L25) | W25: =SUM(C25:H25) | X25: =SUM(I25:J25) | Z25: Net General insurance liabilities | AJ25: =AJ24+B87
A26: I.E. Debt securities | B26: 28400 | C26: =SUM(C27:C32) | D26: =SUM(D27:D32) | E26: =SUM(E27:E32) | F26: =SUM(F27:F32) | G26: =SUM(G27:G32) | H26: =SUM(H27:H32) | I26: =SUM(I27:I32) | J26: =SUM(J27:J32) | ... L26: =SUM(L27:L32) | N26: =SUM(N27:N32) | P26: =SUM(P27:P32) | R26: =SUM(R27:R32) | T26: =SUM(T27:T32) | W26: =SUM(C26:H26) | X26: =SUM(I26:J26)
A27: I.E1. Sovereign issued | B27: 6200 | W27: =SUM(C27:H27) | X27: =SUM(I27:J27)
A28: I.E2. Issued by domestic public sector entity and other public sector entity fully guaranteed by government or central banks | B28: =SUM(C28:L28) | W28: =SUM(C28:H28) | X28: =SUM(I28:J28)
A29: I.E3. Corporate issued | B29: 19500 | W29: =SUM(C29:H29) | X29: =SUM(I29:J29)
A30: I.E4. Asset backed securities | B30: 1800 | W30: =SUM(C30:H30) | X30: =SUM(I30:J30)
A31: I.E5. Other structured securities | B31: =SUM(C31:L31) | W31: =SUM(C31:H31) | X31: =SUM(I31:J31)
A32: I.E6. Other debt securities | B32: 900 | W32: =SUM(C32:H32) | X32: =SUM(I32:J32)
A33: I.F. Equities | B33: 920 | C33: =SUM(C34:C38) | D33: =SUM(D34:D38) | E33: =SUM(E34:E38) | F33: =SUM(F34:F38) | G33: =SUM(G34:G38) | H33: =SUM(H34:H38) | I33: =SUM(I34:I38) | J33: =SUM(J34:J38) | ... L33: =SUM(L34:L38) | N33: =SUM(N34:N38) | P33: =SUM(P34:P38) | R33: =SUM(R34:R38) | T33: =SUM(T34:T38) | W33: =SUM(C33:H33) | X33: =SUM(I33:J33)
A34: I.F1. Listed equities | B34: 920 | W34: =SUM(C34:H34) | X34: =SUM(I34:J34)
A35: I.F2. Unlisted or private equities | B35: =SUM(C35:L35) | W35: =SUM(C35:H35) | X35: =SUM(I35:J35)
A36: I.F3. Portfolio Investment | B36: =SUM(C36:L36) | W36: =SUM(C36:H36) | X36: =SUM(I36:J36)
A37: I.F4. Hybrid equities and preference equities | B37: =SUM(C37:L37) | W37: =SUM(C37:H37) | X37: =SUM(I37:J37)
A38: I.F5. Strategic investments | B38: =SUM(C38:L38) | W38: =SUM(C38:H38) | X38: =SUM(I38:J38)
A39: I.G. Derivative financial instruments | B39: =SUM(C39:L39) | W39: =SUM(C39:H39) | X39: =SUM(I39:J39)
A40: I.H. Properties | B40: =SUM(B41:B42) | C40: =SUM(C41:C42) | D40: =SUM(D41:D42) | E40: =SUM(E41:E42) | F40: =SUM(F41:F42) | G40: =SUM(G41:G42) | H40: =SUM(H41:H42) | I40: =SUM(I41:I42) | ... L40: =SUM(L41:L42) | N40: =SUM(N41:N42) | P40: =SUM(P41:P42) | R40: =SUM(R41:R42) | T40: =SUM(T41:T42) | W40: =SUM(C40:H40) | X40: =SUM(I40:J40)
A41: I.H1. Investment properties | B41: =SUM(C41:L41) | W41: =SUM(C41:H41) | X41: =SUM(I41:J41)
A42: I.H2. Own-occupied properties | B42: =SUM(C42:L42) | W42: =SUM(C42:H42) | X42: =SUM(I42:J42)
A43: I.I. Policyholder account assets in respect of unit-linked products / account value for retirement scheme | B43: =SUM(C43:L43) | W43: =SUM(C43:H43)
A44: I.J. Loans and advances | B44: 1150 | C44: =SUM(C45:C46) | D44: =SUM(D45:D46) | E44: =SUM(E45:E46) | F44: =SUM(F45:F46) | G44: =SUM(G45:G46) | H44: =SUM(H45:H46) | I44: =SUM(I45:I46) | J44: =SUM(J45:J46) | ... L44: =SUM(L45:L46) | N44: =SUM(N45:N46) | P44: =SUM(P45:P46) | R44: =SUM(R45:R46) | T44: =SUM(T45:T46) | W44: =SUM(C44:H44) | X44: =SUM(I44:J44)
...

Sheet F.LT.1.1 LT CE Summary
A1: F.LT.1.1 Summary of current estimate for long term business
A2: Name of Insurer: | B2: ='Cover Page'!F15
A3: Valuation Date: | B3: 31 Dec 2025
A4: Reporting Period:
A7: (Unit: in HKD thousands)
A8: Column 1 | B8: Column 2 | C8: Column 3 | D8: Column 4 | E8: Column 5 | F8: Column 6 | H8: Column 7 | I8: Column 8 | J8: Column 9 | K8: Column 10
A9: Lines of business classification | B9: Current estimate (excluding the offshore RI business in the case of branches operating in Hong Kong, where offshore RI fund is established) | H9: Current estimate (Gross of RI ceded) (including the offshore RI business)
B10: Deterministic current estimate (Gross of RI ceded) | C10: Time value of options and guarantees (TVOG) | D10: Current estimate (Gross of RI ceded) | E10: RI ceded | F10: Current estimate (Net of RI ceded) | H10: Onshore - Direct | I10: Onshore - Inward RI | J10: Offshore - Direct | K10: Offshore - Inward RI
A11: Total Business | B11: 23850 | C11: =SUM(C30,C12,C24,C27,C42) | D11: 23850 | E11: =SUM(E30,E12,E24,E27,E42) | F11: =D11-E11 | H11: =SUM(H30,H12,H24,H27,H42) | I11: =SUM(I30,I12,I24,I27,I42) | J11: =SUM(J30,J12,J24,J27,J42) | K11: =SUM(K30,K12,K24,K27,K42)
A12: Linked Long Term (Class C) | B12: 0 | C12: =SUM(C13,C16,C19:C23) | D12: 0 | E12: =SUM(E13,E16,E19:E23) | F12: =D12-E12 | H12: =SUM(H13,H16,H19:H23) | I12: =SUM(I13,I16,I19:I23) | J12: =SUM(J13,J16,J19:J23) | K12: =SUM(K13,K16,K19:K23)
A13: Unit Linked | B13: 0 | C13: =SUM(C14:C15) | D13: 0 | E13: =SUM(E14:E15) | F13: =D13-E13 | H13: =SUM(H14:H15) | I13: =SUM(I14:I15) | J13: =SUM(J14:J15) | K13: =SUM(K14:K15)
A14: Unit Linked - Unit Reserves | B14: 0 | D14: 0 | F14: =D14-E14
A15: Unit Linked - Non-Unit Reserves | B15: 0 | D15: 0 | F15: =D15-E15
A16: Indexed Universal Life | B16: =SUM(B17:B18) | C16: =SUM(C17:C18) | D16: =B16+C16 | E16: =SUM(E17:E18) | F16: =D16-E16 | H16: =SUM(H17:H18) | I16: =SUM(I17:I18) | J16: =SUM(J17:J18) | K16: =SUM(K17:K18)
A17: Indexed Universal Life - Account Balance | D17: =B17+C17 | F17: =D17-E17
A18: Indexed Universal Life - Other Reserves | D18: =B18+C18 | F18: =D18-E18
A19: Term | B19: 500 | D19: 500 | F19: =D19-E19
A20: A&H (Medical) | D20: =B20+C20 | F20: =D20-E20
A21: A&H (Critical Illness) | D21: =B21+C21 | F21: =D21-E21
A22: A&H (Accident & Disability) | D22: =B22+C22 | F22: =D22-E22
A23: Others | D23: =B23+C23 | F23: =D23-E23
A24: Retirement Scheme Category I (Class G) | B24: 0 | C24: =SUM(C25:C26) | D24: 0 | E24: =SUM(E25:E26) | F24: =D24-E24 | H24: =SUM(H25:H26) | I24: =SUM(I25:I26) | J24: =SUM(J25:J26) | K24: =SUM(K25:K26)
A25: Class G - Account Balance | D25: =B25+C25 | F25: =D25-E25
A26: Class G - Other Reserves | D26: =B26+C26 | F26: =D26-E26
A27: Retirement Scheme Category II (Class H) | B27: 0 | C27: =SUM(C28:C29) | D27: 0 | E27: =SUM(E28:E29) | F27: =D27-E27 | H27: =SUM(H28:H29) | I27: =SUM(I28:I29) | J27: =SUM(J28:J29) | K27: =SUM(K28:K29)
A28: Class H - Account Balance | D28: =B28+C28 | F28: =D28-E28
A29: Class H - Other Reserves | D29: =B29+C29 | F29: =D29-E29
A30: Participating Business | B30: 18200 | C30: =SUM(C31:C38,C41) | D30: 18200 | E30: =SUM(E31:E38,E41) | F30: =D30-E30 | H30: =SUM(H31:H38,H41) | I30: =SUM(I31:I38,I41) | J30: =SUM(J31:J38,J41) | K30: =SUM(K31:K38,K41)
A31: Whole of Life | B31: 12500 | D31: 12500 | F31: =D31-E31
A32: Endowment | B32: 3800 | D32: 3800 | F32: =D32-E32
A33: Immediate and Deferred Annuities | B33: 1200 | D33: 1200 | F33: =D33-E33
A34: Term | B34: 500 | D34: 500 | F34: =D34-E34
A35: A&H (Medical) | D35: =B35+C35 | F35: =D35-E35
A36: A&H (Critical Illness) | D36: =B36+C36 | F36: =D36-E36
A37: A&H (Accident & Disability) | D37: =B37+C37 | F37: =D37-E37
A38: Policyholders' Funds on Deposit (FOD) | B38: =SUM(B39:B40) | C38: =SUM(C39:C40) | D38: =B38+C38 | E38: =SUM(E39:E40) | F38: =D38-E38 | H38: =SUM(H39:H40) | I38: =SUM(I39:I40) | J38: =SUM(J39:J40) | K38: =SUM(K39:K40)
A39: FOD (Account Balance) | D39: =B39+C39 | F39: =D39-E39
A40: FOD (Other Reserves) | D40: =B40+C40 | F40: =D40-E40
A41: Others | D41: =B41+C41 | F41: =D41-E41
A42: Other Businesses | B42: 5650 | C42: =SUM(C43:C46,C58,C49:C55) | D42: 5650 | E42: =SUM(E43:E46,E58,E49:E55) | F42: =D42-E42 | H42: =SUM(H43:H46,H58,H49:H55) | I42: =SUM(I43:I46,I58,I49:I55) | J42: =SUM(J43:J46,J58,J49:J55) | K42: =SUM(K43:K46,K58,K49:K55)
...

Sheet CA.1 CA Summary
B1: CA.1 Summary of capital requirements
B2: Name of Insurer: | C2: ='Cover Page'!F15
B3: Valuation Date: | C3: 31 Dec 2025
B4: Reporting Period:
B6: (Unit: in HKD thousands)
B7: Column 1 | C7: Column 2 | D7: Column 3 | E7: Column 4 | F7: Column 5
C8: As at end of current reporting period (T)
C9: Total | D9: Tier 1 – unlimited | E9: Tier 1 – limited | F9: Tier 2
B10: Eligible capital
B11: Total eligible capital | C11: 11800 | D11: ='CA.R.1 CB composition'!D41 | E11: ='CA.R.1 CB composition'!E57 | F11: ='CA.R.1 CB composition'!E82
B12: Total Tier 1 eligible capital | C12: 11800 | D12: ='CA.R.1 CB composition'!D41 | E12: ='CA.R.1 CB composition'!E57
C14: Diversified PCA/RCA | D14: RCA after additional management action on FDB | E14: RCA before additional management action on FDB
B15: RCA
B16: Market Risk | C16: 1950
B17: Interest Rate Risk | C17: 0 | D17: =MAX(0,IF('CA.P.1.A PCA Summary NetFDB'!$P$6="Without transition", 'CA.P.1.A PCA Summary NetFDB'!N14,'CA.P.1.A PCA Summary NetFDB'!P14)) | E17: =MAX(0,IF('CA.P.2 PCA Summary GrossFDB'!$P$6="Without transition", 'CA.P.2 PCA Summary GrossFDB'!N14,'CA.P.2 PCA Summary GrossFDB'!P14))
B18: Credit Spread Risk | C18: 0 | D18: =MAX(0,IF('CA.P.1.A PCA Summary NetFDB'!$P$6="Without transition", 'CA.P.1.A PCA Summary NetFDB'!N15,'CA.P.1.A PCA Summary NetFDB'!P15)) | E18: =MAX(0,IF('CA.P.2 PCA Summary GrossFDB'!$P$6="Without transition", 'CA.P.2 PCA Summary GrossFDB'!N15,'CA.P.2 PCA Summary GrossFDB'!P15))
B19: Equity Risk | C19: 0 | D19: =MAX(0,IF('CA.P.1.A PCA Summary NetFDB'!$P$6="Without transition", 'CA.P.1.A PCA Summary NetFDB'!N16,'CA.P.1.A PCA Summary NetFDB'!P16)) | E19: =MAX(0,IF('CA.P.2 PCA Summary GrossFDB'!$P$6="Without transition", 'CA.P.2 PCA Summary GrossFDB'!N16,'CA.P.2 PCA Summary GrossFDB'!P16))
B20: Property Risk | C20: 0 | D20: =MAX(0,IF('CA.P.1.A PCA Summary NetFDB'!$P$6="Without transition", 'CA.P.1.A PCA Summary NetFDB'!N17,'CA.P.1.A PCA Summary NetFDB'!P17)) | E20: =MAX(0,IF('CA.P.2 PCA Summary GrossFDB'!$P$6="Without transition", 'CA.P.2 PCA Summary GrossFDB'!N17,'CA.P.2 PCA Summary GrossFDB'!P17))
B21: Currency Risk | C21: 0 | D21: =MAX(0,IF('CA.P.1.A PCA Summary NetFDB'!$P$6="Without transition", 'CA.P.1.A PCA Summary NetFDB'!N18,'CA.P.1.A PCA Summary NetFDB'!P18)) | E21: =MAX(0,IF('CA.P.2 PCA Summary GrossFDB'!$P$6="Without transition", 'CA.P.2 PCA Summary GrossFDB'!N18,'CA.P.2 PCA Summary GrossFDB'!P18))
B22: Life Insurance Risk | C22: 3100
B23: Mortality Risk | C23: 820 | D23: =MAX(0,IF('CA.P.1.A PCA Summary NetFDB'!$P$6="Without transition", 'CA.P.1.A PCA Summary NetFDB'!N22,'CA.P.1.A PCA Summary NetFDB'!P22)) | E23: =MAX(0,IF('CA.P.2 PCA Summary GrossFDB'!$P$6="Without transition", 'CA.P.2 PCA Summary GrossFDB'!N22,'CA.P.2 PCA Summary GrossFDB'!P22))
B24: Longevity Risk | C24: 90 | D24: =MAX(0,IF('CA.P.1.A PCA Summary NetFDB'!$P$6="Without transition", 'CA.P.1.A PCA Summary NetFDB'!N23,'CA.P.1.A PCA Summary NetFDB'!P23)) | E24: =MAX(0,IF('CA.P.2 PCA Summary GrossFDB'!$P$6="Without transition", 'CA.P.2 PCA Summary GrossFDB'!N23,'CA.P.2 PCA Summary GrossFDB'!P23))
B25: Life Catastrophe Risk | C25: 480 | D25: =MAX(0,IF('CA.P.1.A PCA Summary NetFDB'!$P$6="Without transition", 'CA.P.1.A PCA Summary NetFDB'!N24,'CA.P.1.A PCA Summary NetFDB'!P24)) | E25: =MAX(0,IF('CA.P.2 PCA Summary GrossFDB'!$P$6="Without transition", 'CA.P.2 PCA Summary GrossFDB'!N24,'CA.P.2 PCA Summary GrossFDB'!P24))
B26: Morbidity Risk | C26: 200 | D26: =MAX(0,IF('CA.P.1.A PCA Summary NetFDB'!$P$6="Without transition", 'CA.P.1.A PCA Summary NetFDB'!N25,'CA.P.1.A PCA Summary NetFDB'!P25)) | E26: =MAX(0,IF('CA.P.2 PCA Summary GrossFDB'!$P$6="Without transition", 'CA.P.2 PCA Summary GrossFDB'!N25,'CA.P.2 PCA Summary GrossFDB'!P25))
B27: Expense Risk | C27: 640 | D27: =MAX(0,IF('CA.P.1.A PCA Summary NetFDB'!$P$6="Without transition", 'CA.P.1.A PCA Summary NetFDB'!N26,'CA.P.1.A PCA Summary NetFDB'!P26)) | E27: =MAX(0,IF('CA.P.2 PCA Summary GrossFDB'!$P$6="Without transition", 'CA.P.2 PCA Summary GrossFDB'!N26,'CA.P.2 PCA Summary GrossFDB'!P26))
B28: Lapse Risk | C28: 870 | D28: =MAX(0,IF('CA.P.1.A PCA Summary NetFDB'!$P$6="Without transition", 'CA.P.1.A PCA Summary NetFDB'!N27,'CA.P.1.A PCA Summary NetFDB'!P27)) | E28: =MAX(0,IF('CA.P.2 PCA Summary GrossFDB'!$P$6="Without transition", 'CA.P.2 PCA Summary GrossFDB'!N27,'CA.P.2 PCA Summary GrossFDB'!P27))
B29: General Insurance Risk | C29: 0
B30: General Insurance Risk (excluding Mortgage Insurance) | C30: 0
B31: Reserve & Premium Risk | D31: =MAX(0,IF('CA.P.1.A PCA Summary NetFDB'!$P$6="Without transition", 'CA.P.1.A PCA Summary NetFDB'!N32,'CA.P.1.A PCA Summary NetFDB'!P32)) | E31: =MAX(0,IF('CA.P.2 PCA Summary GrossFDB'!$P$6="Without transition", 'CA.P.2 PCA Summary GrossFDB'!N32,'CA.P.2 PCA Summary GrossFDB'!P32))
B32: Natural Catastrophe Risk | D32: =MAX(0,IF('CA.P.1.A PCA Summary NetFDB'!$P$6="Without transition", 'CA.P.1.A PCA Summary NetFDB'!N33,'CA.P.1.A PCA Summary NetFDB'!P33)) | E32: =MAX(0,IF('CA.P.2 PCA Summary GrossFDB'!$P$6="Without transition", 'CA.P.2 PCA Summary GrossFDB'!N33,'CA.P.2 PCA Summary GrossFDB'!P33))
B33: Man-made Non-systemic Catastrophe Risk | D33: =MAX(0,IF('CA.P.1.A PCA Summary NetFDB'!$P$6="Without transition", 'CA.P.1.A PCA Summary NetFDB'!N34,'CA.P.1.A PCA Summary NetFDB'!P34)) | E33: =MAX(0,IF('CA.P.2 PCA Summary GrossFDB'!$P$6="Without transition", 'CA.P.2 PCA Summary GrossFDB'!N34,'CA.P.2 PCA Summary GrossFDB'!P34))
B34: Man-made Systemic Catastrophe Risk | D34: =MAX(0,IF('CA.P.1.A PCA Summary NetFDB'!$P$6="Without transition", 'CA.P.1.A PCA Summary NetFDB'!N35,'CA.P.1.A PCA Summary NetFDB'!P35)) | E34: =MAX(0,IF('CA.P.2 PCA Summary GrossFDB'!$P$6="Without transition", 'CA.P.2 PCA Summary GrossFDB'!N35,'CA.P.2 PCA Summary GrossFDB'!P35))
B35: Mortgage Insurance Risk | C35: 0
B36: Counterparty Default and Other Risk | C36: 180
B37: PCA before Operational Risk (before LAC cap) | C37: 4870
B38: Operational Risk | C38: 520
B39: PCA (before LAC cap) | C39: 5390
B40: Adjustment for LAC cap | C40: -900
B41: Adjustment for tax effect on deferred tax assets | C41: -140
B42: PCA | C42: 4350
...
